Workbook

Sheet Inputs_Population
B2: Year | C2: Total Population | D2: Forcast Total Population | E2: Lower Confidence Bound | F2: Upper Confidence Bound
B3: 2000 | C3: 4027887
B4: 2001 | C4: 4138012
B5: 2002 | C5: 4175950
B6: 2003 | C6: 4114826
B7: 2004 | C7: 4166664
B8: 2005 | C8: 4265762
B9: 2006 | C9: 4401365
B10: 2007 | C10: 4588599
B11: 2008 | C11: 4839396
B12: 2009 | C12: 4987573
B13: 2010 | C13: 5076732
B14: 2011 | C14: 5183688
... B28: 2025 | C28: 6111175
B29: 2026 | D29: =FORECAST(B29,$C$3:$C$28,$B$3:$B$28) -> 6260749.7 | E29: =D29-_xlfn.FORECAST.ETS.CONFINT(B29,$C$3:$C$28,$B$3:$B$28,0.95,1,1) -> 6025618.1 | F29: =D29+_xlfn.FORECAST.ETS.CONFINT(B29,$C$3:$C$28,$B$3:$B$28,0.95,1,1) -> 6495881.4
B30: 2027 | D30: =FORECAST(B30,$C$3:$C$28,$B$3:$B$28) -> 6345344.8 | E30: =D30-_xlfn.FORECAST.ETS.CONFINT(B30,$C$3:$C$28,$B$3:$B$28,0.95,1,1) -> 6051289.1 | F30: =D30+_xlfn.FORECAST.ETS.CONFINT(B30,$C$3:$C$28,$B$3:$B$28,0.95,1,1) -> 6639400.5
B31: 2028 | D31: =FORECAST(B31,$C$3:$C$28,$B$3:$B$28) -> 6429939.8 | E31: =D31-_xlfn.FORECAST.ETS.CONFINT(B31,$C$3:$C$28,$B$3:$B$28,0.95,1,1) -> 6086816.3 | F31: =D31+_xlfn.FORECAST.ETS.CONFINT(B31,$C$3:$C$28,$B$3:$B$28,0.95,1,1) -> 6773063.3
B32: 2029 | D32: =FORECAST(B32,$C$3:$C$28,$B$3:$B$28) -> 6514534.8 | E32: =D32-_xlfn.FORECAST.ETS.CONFINT(B32,$C$3:$C$28,$B$3:$B$28,0.95,1,1) -> 6128423.6 | F32: =D32+_xlfn.FORECAST.ETS.CONFINT(B32,$C$3:$C$28,$B$3:$B$28,0.95,1,1) -> 6900646.1
B33: 2030 | D33: =FORECAST(B33,$C$3:$C$28,$B$3:$B$28) -> 6599129.9 | E33: =D33-_xlfn.FORECAST.ETS.CONFINT(B33,$C$3:$C$28,$B$3:$B$28,0.95,1,1) -> 6174261.2 | F33: =D33+_xlfn.FORECAST.ETS.CONFINT(B33,$C$3:$C$28,$B$3:$B$28,0.95,1,1) -> 7023998.5
B34: 2031 | D34: =FORECAST(B34,$C$3:$C$28,$B$3:$B$28) -> 6683724.9 | E34: =D34-_xlfn.FORECAST.ETS.CONFINT(B34,$C$3:$C$28,$B$3:$B$28,0.95,1,1) -> 6223259.6 | F34: =D34+_xlfn.FORECAST.ETS.CONFINT(B34,$C$3:$C$28,$B$3:$B$28,0.95,1,1) -> 7144190.2
B35: 2032 | D35: =FORECAST(B35,$C$3:$C$28,$B$3:$B$28) -> 6768319.9 | E35: =D35-_xlfn.FORECAST.ETS.CONFINT(B35,$C$3:$C$28,$B$3:$B$28,0.95,1,1) -> 6274734.3 | F35: =D35+_xlfn.FORECAST.ETS.CONFINT(B35,$C$3:$C$28,$B$3:$B$28,0.95,1,1) -> 7261905.5
B36: 2033 | D36: =FORECAST(B36,$C$3:$C$28,$B$3:$B$28) -> 6852914.9 | E36: =D36-_xlfn.FORECAST.ETS.CONFINT(B36,$C$3:$C$28,$B$3:$B$28,0.95,1,1) -> 6328216.1 | F36: =D36+_xlfn.FORECAST.ETS.CONFINT(B36,$C$3:$C$28,$B$3:$B$28,0.95,1,1) -> 7377613.8
B37: 2034 | D37: =FORECAST(B37,$C$3:$C$28,$B$3:$B$28) -> 6937510 | E37: =D37-_xlfn.FORECAST.ETS.CONFINT(B37,$C$3:$C$28,$B$3:$B$28,0.95,1,1) -> 6383366.8 | F37: =D37+_xlfn.FORECAST.ETS.CONFINT(B37,$C$3:$C$28,$B$3:$B$28,0.95,1,1) -> 7491653.2 | H37: Documentation
B38: 2035 | D38: =FORECAST(B38,$C$3:$C$28,$B$3:$B$28) -> 7022105 | E38: =D38-_xlfn.FORECAST.ETS.CONFINT(B38,$C$3:$C$28,$B$3:$B$28,0.95,1,1) -> 6439932.8 | F38: =D38+_xlfn.FORECAST.ETS.CONFINT(B38,$C$3:$C$28,$B$3:$B$28,0.95,1,1) -> 7604277.2 | H38: Total Population | I38: <input>
B39: 2036 | D39: =FORECAST(B39,$C$3:$C$28,$B$3:$B$28) -> 7106700 | E39: =D39-_xlfn.FORECAST.ETS.CONFINT(B39,$C$3:$C$28,$B$3:$B$28,0.95,1,1) -> 6497718.8 | F39: =D39+_xlfn.FORECAST.ETS.CONFINT(B39,$C$3:$C$28,$B$3:$B$28,0.95,1,1) -> 7715681.3 | H39: Forcast Total Population | I39: =FORECAST(B29,$C$3:$C$28,$B$3:$B$28)
B40: 2037 | D40: =FORECAST(B40,$C$3:$C$28,$B$3:$B$28) -> 7191295.1 | E40: =D40-_xlfn.FORECAST.ETS.CONFINT(B40,$C$3:$C$28,$B$3:$B$28,0.95,1,1) -> 6556570 | F40: =D40+_xlfn.FORECAST.ETS.CONFINT(B40,$C$3:$C$28,$B$3:$B$28,0.95,1,1) -> 7826020.2 | H40: Lower Confidence Bound | I40: =D29-FORECAST.ETS.CONFINT(B29,$C$3:$C$28,$B$3:$B$28,0.95,1,1)
B41: 2038 | D41: =FORECAST(B41,$C$3:$C$28,$B$3:$B$28) -> 7275890.1 | E41: =D41-_xlfn.FORECAST.ETS.CONFINT(B41,$C$3:$C$28,$B$3:$B$28,0.95,1,1) -> 6616361.5 | F41: =D41+_xlfn.FORECAST.ETS.CONFINT(B41,$C$3:$C$28,$B$3:$B$28,0.95,1,1) -> 7935418.7 | H41: Upper Confidence Bound | I41: =D29+FORECAST.ETS.CONFINT(B29,$C$3:$C$28,$B$3:$B$28,0.95,1,1)
B42: 2039 | D42: =FORECAST(B42,$C$3:$C$28,$B$3:$B$28) -> 7360485.1 | E42: =D42-_xlfn.FORECAST.ETS.CONFINT(B42,$C$3:$C$28,$B$3:$B$28,0.95,1,1) -> 6676991 | F42: =D42+_xlfn.FORECAST.ETS.CONFINT(B42,$C$3:$C$28,$B$3:$B$28,0.95,1,1) -> 8043979.3
B43: 2040 | D43: =FORECAST(B43,$C$3:$C$28,$B$3:$B$28) -> 7445080.1 | E43: =D43-_xlfn.FORECAST.ETS.CONFINT(B43,$C$3:$C$28,$B$3:$B$28,0.95,1,1) -> 6738373 | F43: =D43+_xlfn.FORECAST.ETS.CONFINT(B43,$C$3:$C$28,$B$3:$B$28,0.95,1,1) -> 8151787.3
B44: 2041 | D44: =FORECAST(B44,$C$3:$C$28,$B$3:$B$28) -> 7529675.2 | E44: =D44-_xlfn.FORECAST.ETS.CONFINT(B44,$C$3:$C$28,$B$3:$B$28,0.95,1,1) -> 6800435.6 | F44: =D44+_xlfn.FORECAST.ETS.CONFINT(B44,$C$3:$C$28,$B$3:$B$28,0.95,1,1) -> 8258914.7
B45: 2042 | D45: =FORECAST(B45,$C$3:$C$28,$B$3:$B$28) -> 7614270.2 | E45: =D45-_xlfn.FORECAST.ETS.CONFINT(B45,$C$3:$C$28,$B$3:$B$28,0.95,1,1) -> 6863117.6 | F45: =D45+_xlfn.FORECAST.ETS.CONFINT(B45,$C$3:$C$28,$B$3:$B$28,0.95,1,1) -> 8365422.8
B46: 2043 | D46: =FORECAST(B46,$C$3:$C$28,$B$3:$B$28) -> 7698865.2 | E46: =D46-_xlfn.FORECAST.ETS.CONFINT(B46,$C$3:$C$28,$B$3:$B$28,0.95,1,1) -> 6926366.1 | F46: =D46+_xlfn.FORECAST.ETS.CONFINT(B46,$C$3:$C$28,$B$3:$B$28,0.95,1,1) -> 8471364.3
B47: 2044 | D47: =FORECAST(B47,$C$3:$C$28,$B$3:$B$28) -> 7783460.3 | E47: =D47-_xlfn.FORECAST.ETS.CONFINT(B47,$C$3:$C$28,$B$3:$B$28,0.95,1,1) -> 6990135.4 | F47: =D47+_xlfn.FORECAST.ETS.CONFINT(B47,$C$3:$C$28,$B$3:$B$28,0.95,1,1) -> 8576785.2
B48: 2045 | D48: =FORECAST(B48,$C$3:$C$28,$B$3:$B$28) -> 7868055.3 | E48: =D48-_xlfn.FORECAST.ETS.CONFINT(B48,$C$3:$C$28,$B$3:$B$28,0.95,1,1) -> 7054385.3 | F48: =D48+_xlfn.FORECAST.ETS.CONFINT(B48,$C$3:$C$28,$B$3:$B$28,0.95,1,1) -> 8681725.3
B49: 2046 | D49: =FORECAST(B49,$C$3:$C$28,$B$3:$B$28) -> 7952650.3 | E49: =D49-_xlfn.FORECAST.ETS.CONFINT(B49,$C$3:$C$28,$B$3:$B$28,0.95,1,1) -> 7119080.6 | F49: =D49+_xlfn.FORECAST.ETS.CONFINT(B49,$C$3:$C$28,$B$3:$B$28,0.95,1,1) -> 8786220.1
B50: 2047 | D50: =FORECAST(B50,$C$3:$C$28,$B$3:$B$28) -> 8037245.3 | E50: =D50-_xlfn.FORECAST.ETS.CONFINT(B50,$C$3:$C$28,$B$3:$B$28,0.95,1,1) -> 7184190.1 | F50: =D50+_xlfn.FORECAST.ETS.CONFINT(B50,$C$3:$C$28,$B$3:$B$28,0.95,1,1) -> 8890300.6
B51: 2048 | D51: =FORECAST(B51,$C$3:$C$28,$B$3:$B$28) -> 8121840.4 | E51: =D51-_xlfn.FORECAST.ETS.CONFINT(B51,$C$3:$C$28,$B$3:$B$28,0.95,1,1) -> 7249685.9 | F51: =D51+_xlfn.FORECAST.ETS.CONFINT(B51,$C$3:$C$28,$B$3:$B$28,0.95,1,1) -> 8993994.9
B52: 2049 | D52: =FORECAST(B52,$C$3:$C$28,$B$3:$B$28) -> 8206435.4 | E52: =D52-_xlfn.FORECAST.ETS.CONFINT(B52,$C$3:$C$28,$B$3:$B$28,0.95,1,1) -> 7315543.2 | F52: =D52+_xlfn.FORECAST.ETS.CONFINT(B52,$C$3:$C$28,$B$3:$B$28,0.95,1,1) -> 9097327.6
B53: 2050 | D53: =FORECAST(B53,$C$3:$C$28,$B$3:$B$28) -> 8291030.4 | E53: =D53-_xlfn.FORECAST.ETS.CONFINT(B53,$C$3:$C$28,$B$3:$B$28,0.95,1,1) -> 7381739.5 | F53: =D53+_xlfn.FORECAST.ETS.CONFINT(B53,$C$3:$C$28,$B$3:$B$28,0.95,1,1) -> 9200321.4
... B63: 2060 | D63: =FORECAST(B63,$C$3:$C$28,$B$3:$B$28) -> 9136980.7 | E63: =D63-_xlfn.FORECAST.ETS.CONFINT(B63,$C$3:$C$28,$B$3:$B$28,0.95,1,1) -> 8058672.4 | F63: =D63+_xlfn.FORECAST.ETS.CONFINT(B63,$C$3:$C$28,$B$3:$B$28,0.95,1,1) -> 10215289

Sheet Inputs_Consumption
B2: Year | C2: Total Consumption (litres/day)^ | D2: Forcast Total Consumption(litres/day)^ | E2: Low_L_per_day | F2: High_L_per_day
B3: 2013 | C3: 151
B4: 2014 | C4: 149
B5: 2015 | C5: 149
B6: 2016 | C6: 148
B7: 2017 | C7: 143
B8: 2018 | C8: 141
B9: 2019 | C9: 141
B10: 2020 | C10: 154
B11: 2021 | C11: 158
B12: 2022 | C12: 149
B13: 2026 | D13: =FORECAST(B13,$C$3:$C$12,$B$3:$B$12) -> 150.72121 | E13: =D13-_xlfn.FORECAST.ETS.CONFINT(B13,$C$3:$C$12,$B$3:$B$12,0.95,1,1) -> 130.55999 | F13: =D13+_xlfn.FORECAST.ETS.CONFINT(B13,$C$3:$C$12,$B$3:$B$12,0.95,1,1) -> 170.88243
B14: 2027 | D14: =FORECAST(B14,$C$3:$C$12,$B$3:$B$12) -> 151.00606 | E14: =D14-_xlfn.FORECAST.ETS.CONFINT(B14,$C$3:$C$12,$B$3:$B$12,0.95,1,1) -> 128.57806 | F14: =D14+_xlfn.FORECAST.ETS.CONFINT(B14,$C$3:$C$12,$B$3:$B$12,0.95,1,1) -> 173.43406
B15: 2028 | D15: =FORECAST(B15,$C$3:$C$12,$B$3:$B$12) -> 151.29091 | E15: =D15-_xlfn.FORECAST.ETS.CONFINT(B15,$C$3:$C$12,$B$3:$B$12,0.95,1,1) -> 126.80072 | F15: =D15+_xlfn.FORECAST.ETS.CONFINT(B15,$C$3:$C$12,$B$3:$B$12,0.95,1,1) -> 175.7811
B16: 2029 | D16: =FORECAST(B16,$C$3:$C$12,$B$3:$B$12) -> 151.57576 | E16: =D16-_xlfn.FORECAST.ETS.CONFINT(B16,$C$3:$C$12,$B$3:$B$12,0.95,1,1) -> 125.17997 | F16: =D16+_xlfn.FORECAST.ETS.CONFINT(B16,$C$3:$C$12,$B$3:$B$12,0.95,1,1) -> 177.97154
B17: 2030 | D17: =FORECAST(B17,$C$3:$C$12,$B$3:$B$12) -> 151.86061 | E17: =D17-_xlfn.FORECAST.ETS.CONFINT(B17,$C$3:$C$12,$B$3:$B$12,0.95,1,1) -> 123.68402 | F17: =D17+_xlfn.FORECAST.ETS.CONFINT(B17,$C$3:$C$12,$B$3:$B$12,0.95,1,1) -> 180.03719
B18: 2031 | D18: =FORECAST(B18,$C$3:$C$12,$B$3:$B$12) -> 152.14545 | E18: =D18-_xlfn.FORECAST.ETS.CONFINT(B18,$C$3:$C$12,$B$3:$B$12,0.95,1,1) -> 122.29053 | F18: =D18+_xlfn.FORECAST.ETS.CONFINT(B18,$C$3:$C$12,$B$3:$B$12,0.95,1,1) -> 182.00038
B19: 2032 | D19: =FORECAST(B19,$C$3:$C$12,$B$3:$B$12) -> 152.4303 | E19: =D19-_xlfn.FORECAST.ETS.CONFINT(B19,$C$3:$C$12,$B$3:$B$12,0.95,1,1) -> 120.98308 | F19: =D19+_xlfn.FORECAST.ETS.CONFINT(B19,$C$3:$C$12,$B$3:$B$12,0.95,1,1) -> 183.87752
B20: 2033 | D20: =FORECAST(B20,$C$3:$C$12,$B$3:$B$12) -> 152.71515 | E20: =D20-_xlfn.FORECAST.ETS.CONFINT(B20,$C$3:$C$12,$B$3:$B$12,0.95,1,1) -> 119.7492 | F20: =D20+_xlfn.FORECAST.ETS.CONFINT(B20,$C$3:$C$12,$B$3:$B$12,0.95,1,1) -> 185.6811
B21: 2034 | D21: =FORECAST(B21,$C$3:$C$12,$B$3:$B$12) -> 153 | E21: =D21-_xlfn.FORECAST.ETS.CONFINT(B21,$C$3:$C$12,$B$3:$B$12,0.95,1,1) -> 118.57915 | F21: =D21+_xlfn.FORECAST.ETS.CONFINT(B21,$C$3:$C$12,$B$3:$B$12,0.95,1,1) -> 187.42085
B22: 2035 | D22: =FORECAST(B22,$C$3:$C$12,$B$3:$B$12) -> 153.28485 | E22: =D22-_xlfn.FORECAST.ETS.CONFINT(B22,$C$3:$C$12,$B$3:$B$12,0.95,1,1) -> 117.46513 | F22: =D22+_xlfn.FORECAST.ETS.CONFINT(B22,$C$3:$C$12,$B$3:$B$12,0.95,1,1) -> 189.10456
B23: 2036 | D23: =FORECAST(B23,$C$3:$C$12,$B$3:$B$12) -> 153.5697 | E23: =D23-_xlfn.FORECAST.ETS.CONFINT(B23,$C$3:$C$12,$B$3:$B$12,0.95,1,1) -> 116.40084 | F23: =D23+_xlfn.FORECAST.ETS.CONFINT(B23,$C$3:$C$12,$B$3:$B$12,0.95,1,1) -> 190.73856
B24: 2037 | D24: =FORECAST(B24,$C$3:$C$12,$B$3:$B$12) -> 153.85455 | E24: =D24-_xlfn.FORECAST.ETS.CONFINT(B24,$C$3:$C$12,$B$3:$B$12,0.95,1,1) -> 115.38102 | F24: =D24+_xlfn.FORECAST.ETS.CONFINT(B24,$C$3:$C$12,$B$3:$B$12,0.95,1,1) -> 192.32807
... B41: 2054 | D41: =FORECAST(B41,$C$3:$C$12,$B$3:$B$12) -> 158.69697 | E41: =D41-_xlfn.FORECAST.ETS.CONFINT(B41,$C$3:$C$12,$B$3:$B$12,0.95,1,1) -> 102.20661 | F41: =D41+_xlfn.FORECAST.ETS.CONFINT(B41,$C$3:$C$12,$B$3:$B$12,0.95,1,1) -> 215.18733
B42: 2055 | D42: =FORECAST(B42,$C$3:$C$12,$B$3:$B$12) -> 158.98182 | E42: =D42-_xlfn.FORECAST.ETS.CONFINT(B42,$C$3:$C$12,$B$3:$B$12,0.95,1,1) -> 101.5904 | F42: =D42+_xlfn.FORECAST.ETS.CONFINT(B42,$C$3:$C$12,$B$3:$B$12,0.95,1,1) -> 216.37323 | H42: Documentation
B43: 2056 | D43: =FORECAST(B43,$C$3:$C$12,$B$3:$B$12) -> 159.26667 | E43: =D43-_xlfn.FORECAST.ETS.CONFINT(B43,$C$3:$C$12,$B$3:$B$12,0.95,1,1) -> 100.98624 | F43: =D43+_xlfn.FORECAST.ETS.CONFINT(B43,$C$3:$C$12,$B$3:$B$12,0.95,1,1) -> 217.54709 | H43: Total Population | I43: <input>
B44: 2057 | D44: =FORECAST(B44,$C$3:$C$12,$B$3:$B$12) -> 159.55152 | E44: =D44-_xlfn.FORECAST.ETS.CONFINT(B44,$C$3:$C$12,$B$3:$B$12,0.95,1,1) -> 100.39357 | F44: =D44+_xlfn.FORECAST.ETS.CONFINT(B44,$C$3:$C$12,$B$3:$B$12,0.95,1,1) -> 218.70946 | H44: Forcast Total Population | I44: =FORECAST(B13,$C$3:$C$12,$B$3:$B$12)
B45: 2058 | D45: =FORECAST(B45,$C$3:$C$12,$B$3:$B$12) -> 159.83636 | E45: =D45-_xlfn.FORECAST.ETS.CONFINT(B45,$C$3:$C$12,$B$3:$B$12,0.95,1,1) -> 99.811889 | F45: =D45+_xlfn.FORECAST.ETS.CONFINT(B45,$C$3:$C$12,$B$3:$B$12,0.95,1,1) -> 219.86084 | H45: Lower Confidence Bound | I45: =D13-FORECAST.ETS.CONFINT(B13,$C$3:$C$12,$B$3:$B$12,0.95,1,1)
B46: 2059 | D46: =FORECAST(B46,$C$3:$C$12,$B$3:$B$12) -> 160.12121 | E46: =D46-_xlfn.FORECAST.ETS.CONFINT(B46,$C$3:$C$12,$B$3:$B$12,0.95,1,1) -> 99.240725 | F46: =D46+_xlfn.FORECAST.ETS.CONFINT(B46,$C$3:$C$12,$B$3:$B$12,0.95,1,1) -> 221.0017 | H46: Upper Confidence Bound | I46: =D13+FORECAST.ETS.CONFINT(B13,$C$3:$C$12,$B$3:$B$12,0.95,1,1)
B47: 2060 | D47: =FORECAST(B47,$C$3:$C$12,$B$3:$B$12) -> 160.40606 | E47: =D47-_xlfn.FORECAST.ETS.CONFINT(B47,$C$3:$C$12,$B$3:$B$12,0.95,1,1) -> 98.679639 | F47: =D47+_xlfn.FORECAST.ETS.CONFINT(B47,$C$3:$C$12,$B$3:$B$12,0.95,1,1) -> 222.13248

Sheet Inputs_Tariff
B2: Year | C2: Tariff_$per_m3 | D2: Forecast Tariff_$per_m | E2: Elasticity | F2: TariffIncrease_% | G2: Consumption before tariff | H2: AdjustedConsumption_L_per_day
B3: 2025 | C3: 1.43
B4: 2026 | D4: =C3*(1+F4) -> 1.43 | E4: ='Sensitivity Analysis'!C44 -> -0.2 | F4: ='Trade-off Analysis'!F3 -> 0 | G4: =IF('Trade-off Analysis'!$C$3='Trade-off Analysis'!$I$3,Inputs_Consumption!D13,IF('Trade-off Analysis'!$C$3='Trade-off Analysis'!$I$4,Inputs_Consumption!E13,Inputs_Consumption!F13)) -> 150.72121 | H4: =G4*(1+E4*F4) -> 150.72121
B5: 2027 | D5: =D4*(1+F5) -> 1.43 | E5: =E4 -> -0.2 | F5: ='Trade-off Analysis'!F4 -> 0 | G5: =IF('Trade-off Analysis'!$C$3='Trade-off Analysis'!$I$3,Inputs_Consumption!D14,IF('Trade-off Analysis'!$C$3='Trade-off Analysis'!$I$4,Inputs_Consumption!E14,Inputs_Consumption!F14)) -> 151.00606 | H5: =G5*(1+E5*F5) -> 151.00606
B6: 2028 | D6: =D5*(1+F6) -> 1.43 | E6: =E5 -> -0.2 | F6: ='Trade-off Analysis'!F5 -> 0 | G6: =IF('Trade-off Analysis'!$C$3='Trade-off Analysis'!$I$3,Inputs_Consumption!D15,IF('Trade-off Analysis'!$C$3='Trade-off Analysis'!$I$4,Inputs_Consumption!E15,Inputs_Consumption!F15)) -> 151.29091 | H6: =G6*(1+E6*F6) -> 151.29091
B7: 2029 | D7: =D6*(1+F7) -> 1.43 | E7: =E6 -> -0.2 | F7: ='Trade-off Analysis'!F6 -> 0 | G7: =IF('Trade-off Analysis'!$C$3='Trade-off Analysis'!$I$3,Inputs_Consumption!D16,IF('Trade-off Analysis'!$C$3='Trade-off Analysis'!$I$4,Inputs_Consumption!E16,Inputs_Consumption!F16)) -> 151.57576 | H7: =G7*(1+E7*F7) -> 151.57576
B8: 2030 | D8: =D7*(1+F8) -> 1.43 | E8: =E7 -> -0.2 | F8: ='Trade-off Analysis'!F7 -> 0 | G8: =IF('Trade-off Analysis'!$C$3='Trade-off Analysis'!$I$3,Inputs_Consumption!D17,IF('Trade-off Analysis'!$C$3='Trade-off Analysis'!$I$4,Inputs_Consumption!E17,Inputs_Consumption!F17)) -> 151.86061 | H8: =G8*(1+E8*F8) -> 151.86061
B9: 2031 | D9: =D8*(1+F9) -> 1.43 | E9: =E8 -> -0.2 | F9: ='Trade-off Analysis'!F8 -> 0 | G9: =IF('Trade-off Analysis'!$C$3='Trade-off Analysis'!$I$3,Inputs_Consumption!D18,IF('Trade-off Analysis'!$C$3='Trade-off Analysis'!$I$4,Inputs_Consumption!E18,Inputs_Consumption!F18)) -> 152.14545 | H9: =G9*(1+E9*F9) -> 152.14545
B10: 2032 | D10: =D9*(1+F10) -> 1.43 | E10: =E9 -> -0.2 | F10: ='Trade-off Analysis'!F9 -> 0 | G10: =IF('Trade-off Analysis'!$C$3='Trade-off Analysis'!$I$3,Inputs_Consumption!D19,IF('Trade-off Analysis'!$C$3='Trade-off Analysis'!$I$4,Inputs_Consumption!E19,Inputs_Consumption!F19)) -> 152.4303 | H10: =G10*(1+E10*F10) -> 152.4303
B11: 2033 | D11: =D10*(1+F11) -> 1.43 | E11: =E10 -> -0.2 | F11: ='Trade-off Analysis'!F10 -> 0 | G11: =IF('Trade-off Analysis'!$C$3='Trade-off Analysis'!$I$3,Inputs_Consumption!D20,IF('Trade-off Analysis'!$C$3='Trade-off Analysis'!$I$4,Inputs_Consumption!E20,Inputs_Consumption!F20)) -> 152.71515 | H11: =G11*(1+E11*F11) -> 152.71515
B12: 2034 | D12: =D11*(1+F12) -> 1.43 | E12: =E11 -> -0.2 | F12: ='Trade-off Analysis'!F11 -> 0 | G12: =IF('Trade-off Analysis'!$C$3='Trade-off Analysis'!$I$3,Inputs_Consumption!D21,IF('Trade-off Analysis'!$C$3='Trade-off Analysis'!$I$4,Inputs_Consumption!E21,Inputs_Consumption!F21)) -> 153 | H12: =G12*(1+E12*F12) -> 153
B13: 2035 | D13: =D12*(1+F13) -> 1.43 | E13: =E12 -> -0.2 | F13: ='Trade-off Analysis'!F12 -> 0 | G13: =IF('Trade-off Analysis'!$C$3='Trade-off Analysis'!$I$3,Inputs_Consumption!D22,IF('Trade-off Analysis'!$C$3='Trade-off Analysis'!$I$4,Inputs_Consumption!E22,Inputs_Consumption!F22)) -> 153.28485 | H13: =G13*(1+E13*F13) -> 153.28485
B14: 2036 | D14: =D13*(1+F14) -> 1.43 | E14: =E13 -> -0.2 | F14: ='Trade-off Analysis'!F13 -> 0 | G14: =IF('Trade-off Analysis'!$C$3='Trade-off Analysis'!$I$3,Inputs_Consumption!D23,IF('Trade-off Analysis'!$C$3='Trade-off Analysis'!$I$4,Inputs_Consumption!E23,Inputs_Consumption!F23)) -> 153.5697 | H14: =G14*(1+E14*F14) -> 153.5697
B15: 2037 | D15: =D14*(1+F15) -> 1.43 | E15: =E14 -> -0.2 | F15: ='Trade-off Analysis'!F14 -> 0 | G15: =IF('Trade-off Analysis'!$C$3='Trade-off Analysis'!$I$3,Inputs_Consumption!D24,IF('Trade-off Analysis'!$C$3='Trade-off Analysis'!$I$4,Inputs_Consumption!E24,Inputs_Consumption!F24)) -> 153.85455 | H15: =G15*(1+E15*F15) -> 153.85455
B16: 2038 | D16: =D15*(1+F16) -> 1.43 | E16: =E15 -> -0.2 | F16: ='Trade-off Analysis'!F15 -> 0 | G16: =IF('Trade-off Analysis'!$C$3='Trade-off Analysis'!$I$3,Inputs_Consumption!D25,IF('Trade-off Analysis'!$C$3='Trade-off Analysis'!$I$4,Inputs_Consumption!E25,Inputs_Consumption!F25)) -> 154.13939 | H16: =G16*(1+E16*F16) -> 154.13939
... B38: 2060 | D38: =D37*(1+F38) -> 3.8057804 | E38: =E37 -> -0.2 | F38: ='Trade-off Analysis'!F37 -> 0.36814253 | G38: =IF('Trade-off Analysis'!$C$3='Trade-off Analysis'!$I$3,Inputs_Consumption!D47,IF('Trade-off Analysis'!$C$3='Trade-off Analysis'!$I$4,Inputs_Consumption!E47,Inputs_Consumption!F47)) -> 160.40606 | H38: =G38*(1+E38*F38) -> 148.5956
B42: Documentation
B43: Tariff_$per_m3 | C43: <input>
B44: Forecast Tariff_$per_m | C44: =D4*(1+F5)
B45: Elasticity | C45: ='Sensitivity Analysis'!C39
B46: TariffIncrease_% | C46: =Optimization!F3:F37
B47: AdjustedConsumption_L_per_day | C47: =IF(Optimization!$C$3=Optimization!$I$3,Inputs_Consumption!D13,IF(Optimization!$C$3=Optimization!$I$4,Inputs_Consumption!E13,Inputs_Consumption!F13))

Sheet Inputs_Supply
B2: Year | C2: LocalCatchment_m3 | D2: Imported_m3 | E2: NEWater_m3 | F2: Desalination_m3 | G2: TotalSupply_m3 | I2: MGD to M3 | J2: 3785.4118 | N2: Subtotal (Desal) | O2: Subtotal (NEWater)
B3: 2025 | C3: =$J$29 -> 2.9582118e+08 | D3: =IF(B3<=$J$54, $J$50*$J$2*365 * IF($J$56=1, $J$51 * IF(RAND()<$J$52, 1-$J$53, 1), $J$55 ), 0 ) -> 3.2158493e+08 | E3: =SUM($N$12:$N$15)*365 -> 2.0172459e+08 | F3: =SUM($N$7:$N$11)*365 -> 2.1001465e+08 | G3: =SUM(C3:F3) -> 1.0291454e+09 | L3: Year ('25, '27, '35) | M3: 2060 | N3: =SUMIFS($N$7:$N$18, $J$7:$J$18, "Desal", $K$7:$K$18, "<=" & $M$3) -> 575382.59 | O3: =SUMIFS($N$7:$N$18, $J$7:$J$18, "NEwater", $K$7:$K$18, "<=" & $M$3) -> 2000211.6
B4: 2026 | C4: =MAX($J$32, $J$29 * (1+$J$30)^(B4-$J$23) * IF($J$56=1, EXP(-0.5*$J$34^2 + $J$34*_xlfn.NORM.S.INV(RAND())), 1) ) -> 2.9582118e+08 | D4: =IF(B4<=$J$54, $J$50*$J$2*365 * IF($J$56=1, $J$51 * IF(RAND()<$J$52, 1-$J$53, 1), $J$55 ), 0 ) -> 3.2158493e+08 | E4: =SUM($N$12:$N$15)*365 -> 2.0172459e+08 | F4: =SUM($N$7:$N$11)*365 -> 2.1001465e+08 | G4: =SUM(C4:F4) -> 1.0291454e+09 | L4: Cap factor (%) (80, 90, 95) | M4: 0.8
B5: 2027 | C5: =MAX($J$32, $J$29 * (1+$J$30)^(B5-$J$23) * IF($J$56=1, EXP(-0.5*$J$34^2 + $J$34*_xlfn.NORM.S.INV(RAND())), 1) ) -> 2.9582118e+08 | D5: =IF(B5<=$J$54, $J$50*$J$2*365 * IF($J$56=1, $J$51 * IF(RAND()<$J$52, 1-$J$53, 1), $J$55 ), 0 ) -> 3.2158493e+08 | E5: =SUM($N$12:$N$16)*365 -> 4.3605673e+08 | F5: =SUM($N$7:$N$11)*365 -> 2.1001465e+08 | G5: =SUM(C5:F5) -> 1.2634775e+09
B6: 2028 | C6: =MAX($J$32, $J$29 * (1+$J$30)^(B6-$J$23) * IF($J$56=1, EXP(-0.5*$J$34^2 + $J$34*_xlfn.NORM.S.INV(RAND())), 1) ) -> 2.9582118e+08 | D6: =IF(B6<=$J$54, $J$50*$J$2*365 * IF($J$56=1, $J$51 * IF(RAND()<$J$52, 1-$J$53, 1), $J$55 ), 0 ) -> 3.2158493e+08 | E6: =SUM($N$12:$N$16)*365 -> 4.3605673e+08 | F6: =SUM($N$7:$N$11)*365 -> 2.1001465e+08 | G6: =SUM(C6:F6) -> 1.2634775e+09 | I6: Plant | J6: Type | K6: Opened | L6: Capacity (mgd) | M6: Production (mgd) | N6: Production (m3d) | O6: Cost ($m)
B7: 2029 | C7: =MAX($J$32, $J$29 * (1+$J$30)^(B7-$J$23) * IF($J$56=1, EXP(-0.5*$J$34^2 + $J$34*_xlfn.NORM.S.INV(RAND())), 1) ) -> 2.9582118e+08 | D7: =IF(B7<=$J$54, $J$50*$J$2*365 * IF($J$56=1, $J$51 * IF(RAND()<$J$52, 1-$J$53, 1), $J$55 ), 0 ) -> 3.2158493e+08 | E7: =SUM($N$12:$N$16)*365 -> 4.3605673e+08 | F7: =SUM($N$7:$N$11)*365 -> 2.1001465e+08 | G7: =SUM(C7:F7) -> 1.2634775e+09 | I7: SingSpring (Tuas) | J7: Desal | K7: 2005 | L7: 30 | M7: =L7*$M$4 -> 24 | N7: =M7*$J$2 -> 90849.883 | O7: 200
B8: 2030 | C8: =MAX($J$32, $J$29 * (1+$J$30)^(B8-$J$23) * IF($J$56=1, EXP(-0.5*$J$34^2 + $J$34*_xlfn.NORM.S.INV(RAND())), 1) ) -> 2.9582118e+08 | D8: =IF(B8<=$J$54, $J$50*$J$2*365 * IF($J$56=1, $J$51 * IF(RAND()<$J$52, 1-$J$53, 1), $J$55 ), 0 ) -> 3.2158493e+08 | E8: =SUM($N$12:$N$16)*365 -> 4.3605673e+08 | F8: =SUM($N$7:$N$11)*365 -> 2.1001465e+08 | G8: =SUM(C8:F8) -> 1.2634775e+09 | I8: Tuas South | J8: Desal | K8: 2013 | L8: 70 | M8: =L8*$M$4 -> 56 | N8: =M8*$J$2 -> 211983.06 | O8: 1050
B9: 2031 | C9: =MAX($J$32, $J$29 * (1+$J$30)^(B9-$J$23) * IF($J$56=1, EXP(-0.5*$J$34^2 + $J$34*_xlfn.NORM.S.INV(RAND())), 1) ) -> 2.9582118e+08 | D9: =IF(B9<=$J$54, $J$50*$J$2*365 * IF($J$56=1, $J$51 * IF(RAND()<$J$52, 1-$J$53, 1), $J$55 ), 0 ) -> 3.2158493e+08 | E9: =SUM($N$12:$N$16)*365 -> 4.3605673e+08 | F9: =SUM($N$7:$N$11)*365 -> 2.1001465e+08 | G9: =SUM(C9:F9) -> 1.2634775e+09 | I9: Tuas Desalination Plant | J9: Desal | K9: 2018 | L9: 30 | M9: =L9*$M$4 -> 24 | N9: =M9*$J$2 -> 90849.883 | O9: 217
B10: 2032 | C10: =MAX($J$32, $J$29 * (1+$J$30)^(B10-$J$23) * IF($J$56=1, EXP(-0.5*$J$34^2 + $J$34*_xlfn.NORM.S.INV(RAND())), 1) ) -> 2.9582118e+08 | D10: =IF(B10<=$J$54, $J$50*$J$2*365 * IF($J$56=1, $J$51 * IF(RAND()<$J$52, 1-$J$53, 1), $J$55 ), 0 ) -> 3.2158493e+08 | E10: =SUM($N$12:$N$16)*365 -> 4.3605673e+08 | F10: =SUM($N$7:$N$11)*365 -> 2.1001465e+08 | G10: =SUM(C10:F10) -> 1.2634775e+09 | I10: Keppel Marina East | J10: Desal | K10: 2020 | L10: 30 | M10: =L10*$M$4 -> 24 | N10: =M10*$J$2 -> 90849.883 | O10: NA
B11: 2033 | C11: =MAX($J$32, $J$29 * (1+$J$30)^(B11-$J$23) * IF($J$56=1, EXP(-0.5*$J$34^2 + $J$34*_xlfn.NORM.S.INV(RAND())), 1) ) -> 2.9582118e+08 | D11: =IF(B11<=$J$54, $J$50*$J$2*365 * IF($J$56=1, $J$51 * IF(RAND()<$J$52, 1-$J$53, 1), $J$55 ), 0 ) -> 3.2158493e+08 | E11: =SUM($N$12:$N$16)*365 -> 4.3605673e+08 | F11: =SUM($N$7:$N$11)*365 -> 2.1001465e+08 | G11: =SUM(C11:F11) -> 1.2634775e+09 | I11: Jurong Island | J11: Desal | K11: 2022 | L11: 30 | M11: =L11*$M$4 -> 24 | N11: =M11*$J$2 -> 90849.883 | O11: NA
B12: 2034 | C12: =MAX($J$32, $J$29 * (1+$J$30)^(B12-$J$23) * IF($J$56=1, EXP(-0.5*$J$34^2 + $J$34*_xlfn.NORM.S.INV(RAND())), 1) ) -> 2.9582118e+08 | D12: =IF(B12<=$J$54, $J$50*$J$2*365 * IF($J$56=1, $J$51 * IF(RAND()<$J$52, 1-$J$53, 1), $J$55 ), 0 ) -> 3.2158493e+08 | E12: =SUM($N$12:$N$16)*365 -> 4.3605673e+08 | F12: =SUM($N$7:$N$11)*365 -> 2.1001465e+08 | G12: =SUM(C12:F12) -> 1.2634775e+09 | I12: Kranji | J12: NEWater | K12: 2003 | L12: 50 | M12: =L12*$M$4 -> 40 | N12: =M12*$J$2 -> 151416.47 | O12: NA
B13: 2035 | C13: =MAX($J$32, $J$29 * (1+$J$30)^(B13-$J$23) * IF($J$56=1, EXP(-0.5*$J$34^2 + $J$34*_xlfn.NORM.S.INV(RAND())), 1) ) -> 2.9582118e+08 | D13: =IF(B13<=$J$54, $J$50*$J$2*365 * IF($J$56=1, $J$51 * IF(RAND()<$J$52, 1-$J$53, 1), $J$55 ), 0 ) -> 3.2158493e+08 | E13: =SUM($N$12:$N$18)*365 -> 7.3007723e+08 | F13: =SUM($N$7:$N$11)*365 -> 2.1001465e+08 | G13: =SUM(C13:F13) -> 1.557498e+09 | I13: Ulu Pandan | J13: NEWater | K13: 2007 | L13: 32.5 | M13: =L13*$M$4 -> 26 | N13: =M13*$J$2 -> 98420.707 | O13: NA
B14: 2036 | C14: =MAX($J$32, $J$29 * (1+$J$30)^(B14-$J$23) * IF($J$56=1, EXP(-0.5*$J$34^2 + $J$34*_xlfn.NORM.S.INV(RAND())), 1) ) -> 2.9582118e+08 | D14: =IF(B14<=$J$54, $J$50*$J$2*365 * IF($J$56=1, $J$51 * IF(RAND()<$J$52, 1-$J$53, 1), $J$55 ), 0 ) -> 3.2158493e+08 | E14: =SUM($N$12:$N$18)*365 -> 7.3007723e+08 | F14: =SUM($N$7:$N$11)*365 -> 2.1001465e+08 | G14: =SUM(C14:F14) -> 1.557498e+09 | I14: Changi (Sembcorp) | J14: NEWater | K14: 2009 | L14: 50 | M14: =L14*$M$4 -> 40 | N14: =M14*$J$2 -> 151416.47 | O14: 180
B15: 2037 | C15: =MAX($J$32, $J$29 * (1+$J$30)^(B15-$J$23) * IF($J$56=1, EXP(-0.5*$J$34^2 + $J$34*_xlfn.NORM.S.INV(RAND())), 1) ) -> 2.9582118e+08 | D15: =IF(B15<=$J$54, $J$50*$J$2*365 * IF($J$56=1, $J$51 * IF(RAND()<$J$52, 1-$J$53, 1), $J$55 ), 0 ) -> 3.2158493e+08 | E15: =SUM($N$12:$N$18)*365 -> 7.3007723e+08 | F15: =SUM($N$7:$N$11)*365 -> 2.1001465e+08 | G15: =SUM(C15:F15) -> 1.557498e+09 | I15: Changi (BEWG) | J15: NEWater | K15: 2017 | L15: 50 | M15: =L15*$M$4 -> 40 | N15: =M15*$J$2 -> 151416.47 | O15: 180
B16: 2038 | C16: =MAX($J$32, $J$29 * (1+$J$30)^(B16-$J$23) * IF($J$56=1, EXP(-0.5*$J$34^2 + $J$34*_xlfn.NORM.S.INV(RAND())), 1) ) -> 2.9582118e+08 | D16: =IF(B16<=$J$54, $J$50*$J$2*365 * IF($J$56=1, $J$51 * IF(RAND()<$J$52, 1-$J$53, 1), $J$55 ), 0 ) -> 3.2158493e+08 | E16: =SUM($N$12:$N$18)*365 -> 7.3007723e+08 | F16: =SUM($N$7:$N$11)*365 -> 2.1001465e+08 | G16: =SUM(C16:F16) -> 1.557498e+09 | I16: Tuas Nexus | J16: NEWater | K16: 2027 | L16: 212 | M16: =L16*$M$4 -> 169.6 | N16: =M16*$J$2 -> 642005.84 | O16: NA
B17: 2039 | C17: =MAX($J$32, $J$29 * (1+$J$30)^(B17-$J$23) * IF($J$56=1, EXP(-0.5*$J$34^2 + $J$34*_xlfn.NORM.S.INV(RAND())), 1) ) -> 2.9582118e+08 | D17: =IF(B17<=$J$54, $J$50*$J$2*365 * IF($J$56=1, $J$51 * IF(RAND()<$J$52, 1-$J$53, 1), $J$55 ), 0 ) -> 3.2158493e+08 | E17: =SUM($N$12:$N$18)*365 -> 7.3007723e+08 | F17: =SUM($N$7:$N$11)*365 -> 2.1001465e+08 | G17: =SUM(C17:F17) -> 1.557498e+09 | I17: Kranji | J17: NEWater | K17: 2035 | L17: 170 | M17: =L17*$M$4 -> 136 | N17: =M17*$J$2 -> 514816 | O17: NA
B18: 2040 | C18: =MAX($J$32, $J$29 * (1+$J$30)^(B18-$J$23) * IF($J$56=1, EXP(-0.5*$J$34^2 + $J$34*_xlfn.NORM.S.INV(RAND())), 1) ) -> 2.9582118e+08 | D18: =IF(B18<=$J$54, $J$50*$J$2*365 * IF($J$56=1, $J$51 * IF(RAND()<$J$52, 1-$J$53, 1), $J$55 ), 0 ) -> 3.2158493e+08 | E18: =SUM($N$12:$N$18)*365 -> 7.3007723e+08 | F18: =SUM($N$7:$N$11)*365 -> 2.1001465e+08 | G18: =SUM(C18:F18) -> 1.557498e+09 | I18: Changi | J18: NEWater | K18: 2035 | L18: 96 | M18: =L18*$M$4 -> 76.8 | N18: =M18*$J$2 -> 290719.63 | O18: NA
B19: 2041 | C19: =MAX($J$32, $J$29 * (1+$J$30)^(B19-$J$23) * IF($J$56=1, EXP(-0.5*$J$34^2 + $J$34*_xlfn.NORM.S.INV(RAND())), 1) ) -> 2.9582118e+08 | D19: =IF(B19<=$J$54, $J$50*$J$2*365 * IF($J$56=1, $J$51 * IF(RAND()<$J$52, 1-$J$53, 1), $J$55 ), 0 ) -> 3.2158493e+08 | E19: =SUM($N$12:$N$18)*365 -> 7.3007723e+08 | F19: =SUM($N$7:$N$11)*365 -> 2.1001465e+08 | G19: =SUM(C19:F19) -> 1.557498e+09
B20: 2042 | C20: =MAX($J$32, $J$29 * (1+$J$30)^(B20-$J$23) * IF($J$56=1, EXP(-0.5*$J$34^2 + $J$34*_xlfn.NORM.S.INV(RAND())), 1) ) -> 2.9582118e+08 | D20: =IF(B20<=$J$54, $J$50*$J$2*365 * IF($J$56=1, $J$51 * IF(RAND()<$J$52, 1-$J$53, 1), $J$55 ), 0 ) -> 3.2158493e+08 | E20: =SUM($N$12:$N$18)*365 -> 7.3007723e+08 | F20: =SUM($N$7:$N$11)*365 -> 2.1001465e+08 | G20: =SUM(C20:F20) -> 1.557498e+09
B21: 2043 | C21: =MAX($J$32, $J$29 * (1+$J$30)^(B21-$J$23) * IF($J$56=1, EXP(-0.5*$J$34^2 + $J$34*_xlfn.NORM.S.INV(RAND())), 1) ) -> 2.9582118e+08 | D21: =IF(B21<=$J$54, $J$50*$J$2*365 * IF($J$56=1, $J$51 * IF(RAND()<$J$52, 1-$J$53, 1), $J$55 ), 0 ) -> 3.2158493e+08 | E21: =SUM($N$12:$N$18)*365 -> 7.3007723e+08 | F21: =SUM($N$7:$N$11)*365 -> 2.1001465e+08 | G21: =SUM(C21:F21) -> 1.557498e+09 | I21: Helper cells for Local Catchment Supply | Q21: ADD GRAPH
B22: 2044 | C22: =MAX($J$32, $J$29 * (1+$J$30)^(B22-$J$23) * IF($J$56=1, EXP(-0.5*$J$34^2 + $J$34*_xlfn.NORM.S.INV(RAND())), 1) ) -> 2.9582118e+08 | D22: =IF(B22<=$J$54, $J$50*$J$2*365 * IF($J$56=1, $J$51 * IF(RAND()<$J$52, 1-$J$53, 1), $J$55 ), 0 ) -> 3.2158493e+08 | E22: =SUM($N$12:$N$18)*365 -> 7.3007723e+08 | F22: =SUM($N$7:$N$11)*365 -> 2.1001465e+08 | G22: =SUM(C22:F22) -> 1.557498e+09
B23: 2045 | C23: =MAX($J$32, $J$29 * (1+$J$30)^(B23-$J$23) * IF($J$56=1, EXP(-0.5*$J$34^2 + $J$34*_xlfn.NORM.S.INV(RAND())), 1) ) -> 2.9582118e+08 | D23: =IF(B23<=$J$54, $J$50*$J$2*365 * IF($J$56=1, $J$51 * IF(RAND()<$J$52, 1-$J$53, 1), $J$55 ), 0 ) -> 3.2158493e+08 | E23: =SUM($N$12:$N$18)*365 -> 7.3007723e+08 | F23: =SUM($N$7:$N$11)*365 -> 2.1001465e+08 | G23: =SUM(C23:F23) -> 1.557498e+09 | I23: Base year | J23: =B3 -> 2025 | K23: Model start year
B24: 2046 | C24: =MAX($J$32, $J$29 * (1+$J$30)^(B24-$J$23) * IF($J$56=1, EXP(-0.5*$J$34^2 + $J$34*_xlfn.NORM.S.INV(RAND())), 1) ) -> 2.9582118e+08 | D24: =IF(B24<=$J$54, $J$50*$J$2*365 * IF($J$56=1, $J$51 * IF(RAND()<$J$52, 1-$J$53, 1), $J$55 ), 0 ) -> 3.2158493e+08 | E24: =SUM($N$12:$N$18)*365 -> 7.3007723e+08 | F24: =SUM($N$7:$N$11)*365 -> 2.1001465e+08 | G24: =SUM(C24:F24) -> 1.557498e+09 | I24: Singapore land area (km2) | J24: =735.7 -> 735.7 | K24: https://data.gov.sg/datasets/d_f74e5ee9575e98ba439bee67e8f9b097/view?dataExplorerPage=7
B25: 2047 | C25: =MAX($J$32, $J$29 * (1+$J$30)^(B25-$J$23) * IF($J$56=1, EXP(-0.5*$J$34^2 + $J$34*_xlfn.NORM.S.INV(RAND())), 1) ) -> 2.9582118e+08 | D25: =IF(B25<=$J$54, $J$50*$J$2*365 * IF($J$56=1, $J$51 * IF(RAND()<$J$52, 1-$J$53, 1), $J$55 ), 0 ) -> 3.2158493e+08 | E25: =SUM($N$12:$N$18)*365 -> 7.3007723e+08 | F25: =SUM($N$7:$N$11)*365 -> 2.1001465e+08 | G25: =SUM(C25:F25) -> 1.557498e+09 | I25: Singapore catchment area (km2) | J25: =$J$24*2/3 -> 490.46667 | K25: 2/3 of land area | L25: https://www.pub.gov.sg/Public/WaterLoop/OurWaterStory/Local-Catchment-Water
B26: 2048 | C26: =MAX($J$32, $J$29 * (1+$J$30)^(B26-$J$23) * IF($J$56=1, EXP(-0.5*$J$34^2 + $J$34*_xlfn.NORM.S.INV(RAND())), 1) ) -> 2.9582118e+08 | D26: =IF(B26<=$J$54, $J$50*$J$2*365 * IF($J$56=1, $J$51 * IF(RAND()<$J$52, 1-$J$53, 1), $J$55 ), 0 ) -> 3.2158493e+08 | E26: =SUM($N$12:$N$18)*365 -> 7.3007723e+08 | F26: =SUM($N$7:$N$11)*365 -> 2.1001465e+08 | G26: =SUM(C26:F26) -> 1.557498e+09 | I26: Mean annual rainfall (mm) | J26: =AVERAGE($J$39:$BA$39) -> 2145.3591
B27: 2049 | C27: =MAX($J$32, $J$29 * (1+$J$30)^(B27-$J$23) * IF($J$56=1, EXP(-0.5*$J$34^2 + $J$34*_xlfn.NORM.S.INV(RAND())), 1) ) -> 2.9582118e+08 | D27: =IF(B27<=$J$54, $J$50*$J$2*365 * IF($J$56=1, $J$51 * IF(RAND()<$J$52, 1-$J$53, 1), $J$55 ), 0 ) -> 3.2158493e+08 | E27: =SUM($N$12:$N$18)*365 -> 7.3007723e+08 | F27: =SUM($N$7:$N$11)*365 -> 2.1001465e+08 | G27: =SUM(C27:F27) -> 1.557498e+09 | I27: Rainfall mean (m) | J27: =J26/1000 -> 2.1453591
B28: 2050 | C28: =MAX($J$32, $J$29 * (1+$J$30)^(B28-$J$23) * IF($J$56=1, EXP(-0.5*$J$34^2 + $J$34*_xlfn.NORM.S.INV(RAND())), 1) ) -> 2.9582118e+08 | D28: =IF(B28<=$J$54, $J$50*$J$2*365 * IF($J$56=1, $J$51 * IF(RAND()<$J$52, 1-$J$53, 1), $J$55 ), 0 ) -> 3.2158493e+08 | E28: =SUM($N$12:$N$18)*365 -> 7.3007723e+08 | F28: =SUM($N$7:$N$11)*365 -> 2.1001465e+08 | G28: =SUM(C28:F28) -> 1.557498e+09 | I28: Effective Yield Coefficient | J28: =J46 -> 0.28113815 | K28: portion of rainfall that ends up in reservoir supply, calibrated from 2001 research study | P28: https://rsis.edu.sg/rsis-publication/rsis/516-singapore-malaysia-and-the-wa/
B29: 2051 | C29: =MAX($J$32, $J$29 * (1+$J$30)^(B29-$J$23) * IF($J$56=1, EXP(-0.5*$J$34^2 + $J$34*_xlfn.NORM.S.INV(RAND())), 1) ) -> 2.9582118e+08 | D29: =IF(B29<=$J$54, $J$50*$J$2*365 * IF($J$56=1, $J$51 * IF(RAND()<$J$52, 1-$J$53, 1), $J$55 ), 0 ) -> 3.2158493e+08 | E29: =SUM($N$12:$N$18)*365 -> 7.3007723e+08 | F29: =SUM($N$7:$N$11)*365 -> 2.1001465e+08 | G29: =SUM(C29:F29) -> 1.557498e+09 | I29: BaselineCatchment (m3) for 2025 | J29: =J27*J25*J28*1000000 -> 2.9582118e+08 | K29: Yield = Rainfall_mean_m × Area_catchment_km2 × 1,000,000 (m² per km²) × Runoff_coeff × Capture_eff
B30: 2052 | C30: =MAX($J$32, $J$29 * (1+$J$30)^(B30-$J$23) * IF($J$56=1, EXP(-0.5*$J$34^2 + $J$34*_xlfn.NORM.S.INV(RAND())), 1) ) -> 2.9582118e+08 | D30: =IF(B30<=$J$54, $J$50*$J$2*365 * IF($J$56=1, $J$51 * IF(RAND()<$J$52, 1-$J$53, 1), $J$55 ), 0 ) -> 3.2158493e+08 | E30: =SUM($N$12:$N$18)*365 -> 7.3007723e+08 | F30: =SUM($N$7:$N$11)*365 -> 2.1001465e+08 | G30: =SUM(C30:F30) -> 1.557498e+09 | I30: Annual climate trend % | J30: 0 | K30: Select option
B31: 2053 | C31: =MAX($J$32, $J$29 * (1+$J$30)^(B31-$J$23) * IF($J$56=1, EXP(-0.5*$J$34^2 + $J$34*_xlfn.NORM.S.INV(RAND())), 1) ) -> 2.9582118e+08 | D31: =IF(B31<=$J$54, $J$50*$J$2*365 * IF($J$56=1, $J$51 * IF(RAND()<$J$52, 1-$J$53, 1), $J$55 ), 0 ) -> 3.2158493e+08 | E31: =SUM($N$12:$N$18)*365 -> 7.3007723e+08 | F31: =SUM($N$7:$N$11)*365 -> 2.1001465e+08 | G31: =SUM(C31:F31) -> 1.557498e+09 | I31: Year-to-year rainfall variability % | J31: =_xlfn.STDEV.S(J39:BA39)/J26 -> 0.20502155 | K31: Inter-annual variability in rainfall, derived from the historial annual rainfall dataset from 1982-2005
B32: 2054 | C32: =MAX($J$32, $J$29 * (1+$J$30)^(B32-$J$23) * IF($J$56=1, EXP(-0.5*$J$34^2 + $J$34*_xlfn.NORM.S.INV(RAND())), 1) ) -> 2.9582118e+08 | D32: =IF(B32<=$J$54, $J$50*$J$2*365 * IF($J$56=1, $J$51 * IF(RAND()<$J$52, 1-$J$53, 1), $J$55 ), 0 ) -> 3.2158493e+08 | E32: =SUM($N$12:$N$18)*365 -> 7.3007723e+08 | F32: =SUM($N$7:$N$11)*365 -> 2.1001465e+08 | G32: =SUM(C32:F32) -> 1.557498e+09 | I32: Floor_m3 | J32: 0 | K32: lower bound for dry years, prevent negatives in extreme draws
B33: 2055 | C33: =MAX($J$32, $J$29 * (1+$J$30)^(B33-$J$23) * IF($J$56=1, EXP(-0.5*$J$34^2 + $J$34*_xlfn.NORM.S.INV(RAND())), 1) ) -> 2.9582118e+08 | D33: =IF(B33<=$J$54, $J$50*$J$2*365 * IF($J$56=1, $J$51 * IF(RAND()<$J$52, 1-$J$53, 1), $J$55 ), 0 ) -> 3.2158493e+08 | E33: =SUM($N$12:$N$18)*365 -> 7.3007723e+08 | F33: =SUM($N$7:$N$11)*365 -> 2.1001465e+08 | G33: =SUM(C33:F33) -> 1.557498e+09
B34: 2056 | C34: =MAX($J$32, $J$29 * (1+$J$30)^(B34-$J$23) * IF($J$56=1, EXP(-0.5*$J$34^2 + $J$34*_xlfn.NORM.S.INV(RAND())), 1) ) -> 2.9582118e+08 | D34: =IF(B34<=$J$54, $J$50*$J$2*365 * IF($J$56=1, $J$51 * IF(RAND()<$J$52, 1-$J$53, 1), $J$55 ), 0 ) -> 3.2158493e+08 | E34: =SUM($N$12:$N$18)*365 -> 7.3007723e+08 | F34: =SUM($N$7:$N$11)*365 -> 2.1001465e+08 | G34: =SUM(C34:F34) -> 1.557498e+09 | I34: Sigma of a lognormal shock | J34: =SQRT(LN(1+$J$31^2)) -> 0.2029148
B35: 2057 | C35: =MAX($J$32, $J$29 * (1+$J$30)^(B35-$J$23) * IF($J$56=1, EXP(-0.5*$J$34^2 + $J$34*_xlfn.NORM.S.INV(RAND())), 1) ) -> 2.9582118e+08 | D35: =IF(B35<=$J$54, $J$50*$J$2*365 * IF($J$56=1, $J$51 * IF(RAND()<$J$52, 1-$J$53, 1), $J$55 ), 0 ) -> 3.2158493e+08 | E35: =SUM($N$12:$N$18)*365 -> 7.3007723e+08 | F35: =SUM($N$7:$N$11)*365 -> 2.1001465e+08 | G35: =SUM(C35:F35) -> 1.557498e+09
B36: 2058 | C36: =MAX($J$32, $J$29 * (1+$J$30)^(B36-$J$23) * IF($J$56=1, EXP(-0.5*$J$34^2 + $J$34*_xlfn.NORM.S.INV(RAND())), 1) ) -> 2.9582118e+08 | D36: =IF(B36<=$J$54, $J$50*$J$2*365 * IF($J$56=1, $J$51 * IF(RAND()<$J$52, 1-$J$53, 1), $J$55 ), 0 ) -> 3.2158493e+08 | E36: =SUM($N$12:$N$18)*365 -> 7.3007723e+08 | F36: =SUM($N$7:$N$11)*365 -> 2.1001465e+08 | G36: =SUM(C36:F36) -> 1.557498e+09
B37: 2059 | C37: =MAX($J$32, $J$29 * (1+$J$30)^(B37-$J$23) * IF($J$56=1, EXP(-0.5*$J$34^2 + $J$34*_xlfn.NORM.S.INV(RAND())), 1) ) -> 2.9582118e+08 | D37: =IF(B37<=$J$54, $J$50*$J$2*365 * IF($J$56=1, $J$51 * IF(RAND()<$J$52, 1-$J$53, 1), $J$55 ), 0 ) -> 3.2158493e+08 | E37: =SUM($N$12:$N$18)*365 -> 7.3007723e+08 | F37: =SUM($N$7:$N$11)*365 -> 2.1001465e+08 | G37: =SUM(C37:F37) -> 1.557498e+09 | K37: Source: sheet RainfallMonthlyTotal from National Environment Agency - https://data.gov.sg/datasets/d_b16d06b83473fdfcc92ed9d37b66ba58/view
B38: 2060 | C38: =MAX($J$32, $J$29 * (1+$J$30)^(B38-$J$23) * IF($J$56=1, EXP(-0.5*$J$34^2 + $J$34*_xlfn.NORM.S.INV(RAND())), 1) ) -> 2.9582118e+08 | D38: =IF(B38<=$J$54, $J$50*$J$2*365 * IF($J$56=1, $J$51 * IF(RAND()<$J$52, 1-$J$53, 1), $J$55 ), 0 ) -> 3.2158493e+08 | E38: =SUM($N$12:$N$18)*365 -> 7.3007723e+08 | F38: =SUM($N$7:$N$11)*365 -> 2.1001465e+08 | G38: =SUM(C38:F38) -> 1.557498e+09 | I38: {=TRANSPOSE(RainfallMonthlyTotal!G1:H45)} -> Year | J38: 1982 | K38: 1983 | L38: 1984 | M38: 1985 | N38: 1986 | O38: 1987 | P38: 1988 | Q38: 1989 | R38: 1990 | S38: 1991 | T38: 1992 | U38: 1993 | V38: 1994 | W38: 1995 | X38: 1996 | Y38: 1997 | Z38: 1998 | AA38: 1999 | AB38: 2000 | AC38: 2001 | AD38: 2002 | AE38: 2003 | AF38: 2004 | AG38: 2005 | AH38: 2006 | AI38: 2007 | AJ38: 2008 | AK38: 2009 | AL38: 2010 | AM38: 2011 | AN38: 2012 | AO38: 2013 | AP38: 2014 | AQ38: 2015 | AR38: 2016 | AS38: 2017 | AT38: 2018 | AU38: 2019 | AV38: 2020 | AW38: 2021 | AX38: 2022 | AY38: 2023 | AZ38: 2024 | BA38: 2025
I39: Annual Rainfall (mm) | J39: 1581.7 | K39: 1993.7 | L39: 2686.7 | M39: 1483.9 | N39: 2536.1 | O39: 2102.8 | P39: 2598.6 | Q39: 2463.2 | R39: 1523.8 | S39: 1877 | T39: 2260.8 | U39: 2168.7 | V39: 1941.8 | W39: 2332.6 | X39: 2418 | Y39: 1118.9 | Z39: 2623.1 | AA39: 2134 | AB39: 2370.5 | AC39: 2783.1 | AD39: 1748.9 | AE39: 2391.2 | AF39: 2136.4 | AG39: 1930.7 | AH39: 2753.2 | AI39: 2886.2 | AJ39: 2325.1 | AK39: 1920.9 | AL39: 2075.1 | AM39: 2524.2 | AN39: 2159.9 | AO39: 2748.4 | AP39: 1538.4 | AQ39: 1267.1 | AR39: 1955.7 | AS39: 2045.6 | AT39: 1708.2 | AU39: 1367.5 | AV39: 1886.6 | AW39: 2809.6 | AX39: 2207.2 | AY39: 2411.2 | AZ39: 2432 | BA39: 2167.5
I42: Mean annual rainfall by 2001 (m) | J42: =2400/1000 -> 2.4
I43: Daily water collected from rainfall (m3) | J43: =680000 -> 680000
...

Sheet RainfallMonthlyTotal
A1: month | B1: total_rainfall | D1: Year | E1: Annual Rainfall (mm) | G1: Year | H1: Annual Rainfall (mm) | K1: Source:
A2: 1982-01 | B2: 107.1 | D2: =YEAR(DATEVALUE(A2 & "-01")) -> 1982 | E2: =SUMIFS($B:$B,$D:$D,D2) -> 1581.7 | G2: {=_xlfn.UNIQUE(D2:D526)} -> 1982 | H2: =_xlfn.XLOOKUP(G2,$D$2:$D$526,$E$2:$E$526) -> 1581.7 | K2: https://data.gov.sg/datasets/d_b16d06b83473fdfcc92ed9d37b66ba58/view
A3: 1982-02 | B3: 27.8 | D3: =YEAR(DATEVALUE(A3 & "-01")) -> 1982 | E3: =SUMIFS($B:$B,$D:$D,D3) -> 1581.7 | G3: 1983 | H3: =_xlfn.XLOOKUP(G3,$D$2:$D$526,$E$2:$E$526) -> 1993.7
A4: 1982-03 | B4: 160.8 | D4: =YEAR(DATEVALUE(A4 & "-01")) -> 1982 | E4: =SUMIFS($B:$B,$D:$D,D4) -> 1581.7 | G4: 1984 | H4: =_xlfn.XLOOKUP(G4,$D$2:$D$526,$E$2:$E$526) -> 2686.7
A5: 1982-04 | B5: 157 | D5: =YEAR(DATEVALUE(A5 & "-01")) -> 1982 | E5: =SUMIFS($B:$B,$D:$D,D5) -> 1581.7 | G5: 1985 | H5: =_xlfn.XLOOKUP(G5,$D$2:$D$526,$E$2:$E$526) -> 1483.9
A6: 1982-05 | B6: 102.2 | D6: =YEAR(DATEVALUE(A6 & "-01")) -> 1982 | E6: =SUMIFS($B:$B,$D:$D,D6) -> 1581.7 | G6: 1986 | H6: =_xlfn.XLOOKUP(G6,$D$2:$D$526,$E$2:$E$526) -> 2536.1
A7: 1982-06 | B7: 59.5 | D7: =YEAR(DATEVALUE(A7 & "-01")) -> 1982 | E7: =SUMIFS($B:$B,$D:$D,D7) -> 1581.7 | G7: 1987 | H7: =_xlfn.XLOOKUP(G7,$D$2:$D$526,$E$2:$E$526) -> 2102.8
A8: 1982-07 | B8: 76.3 | D8: =YEAR(DATEVALUE(A8 & "-01")) -> 1982 | E8: =SUMIFS($B:$B,$D:$D,D8) -> 1581.7 | G8: 1988 | H8: =_xlfn.XLOOKUP(G8,$D$2:$D$526,$E$2:$E$526) -> 2598.6
A9: 1982-08 | B9: 169.5 | D9: =YEAR(DATEVALUE(A9 & "-01")) -> 1982 | E9: =SUMIFS($B:$B,$D:$D,D9) -> 1581.7 | G9: 1989 | H9: =_xlfn.XLOOKUP(G9,$D$2:$D$526,$E$2:$E$526) -> 2463.2
A10: 1982-09 | B10: 54.1 | D10: =YEAR(DATEVALUE(A10 & "-01")) -> 1982 | E10: =SUMIFS($B:$B,$D:$D,D10) -> 1581.7 | G10: 1990 | H10: =_xlfn.XLOOKUP(G10,$D$2:$D$526,$E$2:$E$526) -> 1523.8
A11: 1982-10 | B11: 39.3 | D11: =YEAR(DATEVALUE(A11 & "-01")) -> 1982 | E11: =SUMIFS($B:$B,$D:$D,D11) -> 1581.7 | G11: 1991 | H11: =_xlfn.XLOOKUP(G11,$D$2:$D$526,$E$2:$E$526) -> 1877
A12: 1982-11 | B12: 134 | D12: =YEAR(DATEVALUE(A12 & "-01")) -> 1982 | E12: =SUMIFS($B:$B,$D:$D,D12) -> 1581.7 | G12: 1992 | H12: =_xlfn.XLOOKUP(G12,$D$2:$D$526,$E$2:$E$526) -> 2260.8
A13: 1982-12 | B13: 494.1 | D13: =YEAR(DATEVALUE(A13 & "-01")) -> 1982 | E13: =SUMIFS($B:$B,$D:$D,D13) -> 1581.7 | G13: 1993 | H13: =_xlfn.XLOOKUP(G13,$D$2:$D$526,$E$2:$E$526) -> 2168.7
A14: 1983-01 | B14: 246 | D14: =YEAR(DATEVALUE(A14 & "-01")) -> 1983 | E14: =SUMIFS($B:$B,$D:$D,D14) -> 1993.7 | G14: 1994 | H14: =_xlfn.XLOOKUP(G14,$D$2:$D$526,$E$2:$E$526) -> 1941.8
... A45: 1985-08 | B45: 56.9 | D45: =YEAR(DATEVALUE(A45 & "-01")) -> 1985 | E45: =SUMIFS($B:$B,$D:$D,D45) -> 1483.9 | G45: 2025 | H45: =_xlfn.XLOOKUP(G45,$D$2:$D$526,$E$2:$E$526) -> 2167.5
A46: 1985-09 | B46: 110.7 | D46: =YEAR(DATEVALUE(A46 & "-01")) -> 1985 | E46: =SUMIFS($B:$B,$D:$D,D46) -> 1483.9
A47: 1985-10 | B47: 169 | D47: =YEAR(DATEVALUE(A47 & "-01")) -> 1985 | E47: =SUMIFS($B:$B,$D:$D,D47) -> 1483.9
A48: 1985-11 | B48: 179.4 | D48: =YEAR(DATEVALUE(A48 & "-01")) -> 1985 | E48: =SUMIFS($B:$B,$D:$D,D48) -> 1483.9
A49: 1985-12 | B49: 340.1 | D49: =YEAR(DATEVALUE(A49 & "-01")) -> 1985 | E49: =SUMIFS($B:$B,$D:$D,D49) -> 1483.9
A50: 1986-01 | B50: 308.2 | D50: =YEAR(DATEVALUE(A50 & "-01")) -> 1986 | E50: =SUMIFS($B:$B,$D:$D,D50) -> 2536.1
A51: 1986-02 | B51: 26.7 | D51: =YEAR(DATEVALUE(A51 & "-01")) -> 1986 | E51: =SUMIFS($B:$B,$D:$D,D51) -> 2536.1
A52: 1986-03 | B52: 353.4 | D52: =YEAR(DATEVALUE(A52 & "-01")) -> 1986 | E52: =SUMIFS($B:$B,$D:$D,D52) -> 2536.1
A53: 1986-04 | B53: 150 | D53: =YEAR(DATEVALUE(A53 & "-01")) -> 1986 | E53: =SUMIFS($B:$B,$D:$D,D53) -> 2536.1
A54: 1986-05 | B54: 145.1 | D54: =YEAR(DATEVALUE(A54 & "-01")) -> 1986 | E54: =SUMIFS($B:$B,$D:$D,D54) -> 2536.1
A55: 1986-06 | B55: 122.9 | D55: =YEAR(DATEVALUE(A55 & "-01")) -> 1986 | E55: =SUMIFS($B:$B,$D:$D,D55) -> 2536.1
A56: 1986-07 | B56: 109.7 | D56: =YEAR(DATEVALUE(A56 & "-01")) -> 1986 | E56: =SUMIFS($B:$B,$D:$D,D56) -> 2536.1
A57: 1986-08 | B57: 72.9 | D57: =YEAR(DATEVALUE(A57 & "-01")) -> 1986 | E57: =SUMIFS($B:$B,$D:$D,D57) -> 2536.1
... A526: 2025-09 | B526: 234.2 | D526: =YEAR(DATEVALUE(A526 & "-01")) -> 2025 | E526: =SUMIFS($B:$B,$D:$D,D526) -> 2167.5

Sheet Model_Core
B2: Year | C2: Population | D2: PerCapitaConsumption_Lperday | E2: DomesticDemand_m3 | F2: IndustrialDemand_m3 | G2: TotalDemand_m3 | H2: TotalSupply_m3 | I2: NetBalance_m3 | J2: ReserveMargin_% | L2: Documentation
B3: 2026 | C3: =IF('Trade-off Analysis'!$C$2='Trade-off Analysis'!$I$3,Inputs_Population!D29,IF('Trade-off Analysis'!$C$2='Trade-off Analysis'!$I$4,Inputs_Population!E29,Inputs_Population!F29)) -> 6495881.4 | D3: =Inputs_Tariff!H4 -> 150.72121 | E3: =C3*D3*365/1000 -> 3.573595e+08 | F3: =E3/45*(55+(70-55)*(B3-2025)/35) -> 4.4017614e+08 | G3: =E3+F3 -> 7.9753564e+08 | H3: =Inputs_Supply!G4 -> 1.0291454e+09 | I3: =H3-G3 -> 2.3160971e+08 | J3: =(H3/G3)-1 -> 0.29040672 | L3: Population | M3: C3:C37 | N3: =Inputs_Population!D/E/F29:63 (depends on the scenario)
B4: 2027 | C4: =IF('Trade-off Analysis'!$C$2='Trade-off Analysis'!$I$3,Inputs_Population!D30,IF('Trade-off Analysis'!$C$2='Trade-off Analysis'!$I$4,Inputs_Population!E30,Inputs_Population!F30)) -> 6639400.5 | D4: =Inputs_Tariff!H5 -> 151.00606 | E4: =C4*D4*365/1000 -> 3.6594524e+08 | F4: =E4/45*(55+(70-55)*(B4-2025)/35) -> 4.542368e+08 | G4: =E4+F4 -> 8.2018204e+08 | H4: =Inputs_Supply!G5 -> 1.2634775e+09 | I4: =H4-G4 -> 4.4329544e+08 | J4: =(H4/G4)-1 -> 0.54048421 | L4: PerCapitaConsumption_Lperday | M4: D3:D37 | N4: =Inputs_Consumption!D/E/F13:47 (depends on the scenario)
B5: 2028 | C5: =IF('Trade-off Analysis'!$C$2='Trade-off Analysis'!$I$3,Inputs_Population!D31,IF('Trade-off Analysis'!$C$2='Trade-off Analysis'!$I$4,Inputs_Population!E31,Inputs_Population!F31)) -> 6773063.3 | D5: =Inputs_Tariff!H6 -> 151.29091 | E5: =C5*D5*365/1000 -> 3.7401656e+08 | F5: =E5/45*(55+(70-55)*(B5-2025)/35) -> 4.6781754e+08 | G5: =E5+F5 -> 8.418341e+08 | H5: =Inputs_Supply!G6 -> 1.2634775e+09 | I5: =H5-G5 -> 4.2164339e+08 | J5: =(H5/G5)-1 -> 0.50086281 | L5: DomesticDemand_m3 | M5: E3:E37 | N5: =C3*D3
B6: 2029 | C6: =IF('Trade-off Analysis'!$C$2='Trade-off Analysis'!$I$3,Inputs_Population!D32,IF('Trade-off Analysis'!$C$2='Trade-off Analysis'!$I$4,Inputs_Population!E32,Inputs_Population!F32)) -> 6900646.1 | D6: =Inputs_Tariff!H7 -> 151.57576 | E6: =C6*D6*365/1000 -> 3.8177929e+08 | F6: =E6/45*(55+(70-55)*(B6-2025)/35) -> 4.811631e+08 | G6: =E6+F6 -> 8.6294239e+08 | H6: =Inputs_Supply!G7 -> 1.2634775e+09 | I6: =H6-G6 -> 4.0053509e+08 | J6: =(H6/G6)-1 -> 0.46415044 | L6: IndustrialDemand_m3 | M6: F3:F37 | N6: =E3/45*55+(70-55)*(B3-2025)/35
B7: 2030 | C7: =IF('Trade-off Analysis'!$C$2='Trade-off Analysis'!$I$3,Inputs_Population!D33,IF('Trade-off Analysis'!$C$2='Trade-off Analysis'!$I$4,Inputs_Population!E33,Inputs_Population!F33)) -> 7023998.5 | D7: =Inputs_Tariff!H8 -> 151.86061 | E7: =C7*D7*365/1000 -> 3.8933406e+08 | F7: =E7/45*(55+(70-55)*(B7-2025)/35) -> 4.9439246e+08 | G7: =E7+F7 -> 8.8372653e+08 | H7: =Inputs_Supply!G8 -> 1.2634775e+09 | I7: =H7-G7 -> 3.7975095e+08 | J7: =(H7/G7)-1 -> 0.42971546 | L7: TotalDemand_m3 | M7: G3:G37 | N7: =E3+F3
B8: 2031 | C8: =IF('Trade-off Analysis'!$C$2='Trade-off Analysis'!$I$3,Inputs_Population!D34,IF('Trade-off Analysis'!$C$2='Trade-off Analysis'!$I$4,Inputs_Population!E34,Inputs_Population!F34)) -> 7144190.2 | D8: =Inputs_Tariff!H9 -> 152.14545 | E8: =C8*D8*365/1000 -> 3.9673896e+08 | F8: =E8/45*(55+(70-55)*(B8-2025)/35) -> 5.0757397e+08 | G8: =E8+F8 -> 9.0431294e+08 | H8: =Inputs_Supply!G9 -> 1.2634775e+09 | I8: =H8-G8 -> 3.5916455e+08 | J8: =(H8/G8)-1 -> 0.39716843 | L8: TotalSupply_m3 | M8: H3:H37 | N8: =Inputs_Supply!G3:G38
B9: 2032 | C9: =IF('Trade-off Analysis'!$C$2='Trade-off Analysis'!$I$3,Inputs_Population!D35,IF('Trade-off Analysis'!$C$2='Trade-off Analysis'!$I$4,Inputs_Population!E35,Inputs_Population!F35)) -> 7261905.5 | D9: =Inputs_Tariff!H10 -> 152.4303 | E9: =C9*D9*365/1000 -> 4.0403108e+08 | F9: =E9/45*(55+(70-55)*(B9-2025)/35) -> 5.2075117e+08 | G9: =E9+F9 -> 9.2478224e+08 | H9: =Inputs_Supply!G10 -> 1.2634775e+09 | I9: =H9-G9 -> 3.3869524e+08 | J9: =(H9/G9)-1 -> 0.36624323 | L9: NetBalance_m3 | M9: I3:I37 | N9: =H3-G3
B10: 2033 | C10: =IF('Trade-off Analysis'!$C$2='Trade-off Analysis'!$I$3,Inputs_Population!D36,IF('Trade-off Analysis'!$C$2='Trade-off Analysis'!$I$4,Inputs_Population!E36,Inputs_Population!F36)) -> 7377613.8 | D10: =Inputs_Tariff!H11 -> 152.71515 | E10: =C10*D10*365/1000 -> 4.1123579e+08 | F10: =E10/45*(55+(70-55)*(B10-2025)/35) -> 5.3395377e+08 | G10: =E10+F10 -> 9.4518957e+08 | H10: =Inputs_Supply!G11 -> 1.2634775e+09 | I10: =H10-G10 -> 3.1828792e+08 | J10: =(H10/G10)-1 -> 0.33674506 | L10: ReserveMargin_% | M10: J3:H37 | N10: =H3/G3-1
B11: 2034 | C11: =IF('Trade-off Analysis'!$C$2='Trade-off Analysis'!$I$3,Inputs_Population!D37,IF('Trade-off Analysis'!$C$2='Trade-off Analysis'!$I$4,Inputs_Population!E37,Inputs_Population!F37)) -> 7491653.2 | D11: =Inputs_Tariff!H12 -> 153 | E11: =C11*D11*365/1000 -> 4.1837137e+08 | F11: =E11/45*(55+(70-55)*(B11-2025)/35) -> 5.4720319e+08 | G11: =E11+F11 -> 9.6557456e+08 | H11: =Inputs_Supply!G12 -> 1.2634775e+09 | I11: =H11-G11 -> 2.9790292e+08 | J11: =(H11/G11)-1 -> 0.30852399
B12: 2035 | C12: =IF('Trade-off Analysis'!$C$2='Trade-off Analysis'!$I$3,Inputs_Population!D38,IF('Trade-off Analysis'!$C$2='Trade-off Analysis'!$I$4,Inputs_Population!E38,Inputs_Population!F38)) -> 7604277.2 | D12: =Inputs_Tariff!H13 -> 153.28485 | E12: =C12*D12*365/1000 -> 4.2545147e+08 | F12: =E12/45*(55+(70-55)*(B12-2025)/35) -> 5.6051543e+08 | G12: =E12+F12 -> 9.8596691e+08 | H12: =Inputs_Supply!G13 -> 1.557498e+09 | I12: =H12-G12 -> 5.7153108e+08 | J12: =(H12/G12)-1 -> 0.57966558
B13: 2036 | C13: =IF('Trade-off Analysis'!$C$2='Trade-off Analysis'!$I$3,Inputs_Population!D39,IF('Trade-off Analysis'!$C$2='Trade-off Analysis'!$I$4,Inputs_Population!E39,Inputs_Population!F39)) -> 7715681.3 | D13: =Inputs_Tariff!H14 -> 153.5697 | E13: =C13*D13*365/1000 -> 4.3248661e+08 | F13: =E13/45*(55+(70-55)*(B13-2025)/35) -> 5.7390287e+08 | G13: =E13+F13 -> 1.0063895e+09 | H13: =Inputs_Supply!G14 -> 1.557498e+09 | I13: =H13-G13 -> 5.511085e+08 | J13: =(H13/G13)-1 -> 0.54760956
B14: 2037 | C14: =IF('Trade-off Analysis'!$C$2='Trade-off Analysis'!$I$3,Inputs_Population!D40,IF('Trade-off Analysis'!$C$2='Trade-off Analysis'!$I$4,Inputs_Population!E40,Inputs_Population!F40)) -> 7826020.2 | D14: =Inputs_Tariff!H15 -> 153.85455 | E14: =C14*D14*365/1000 -> 4.394851e+08 | F14: =E14/45*(55+(70-55)*(B14-2025)/35) -> 5.8737533e+08 | G14: =E14+F14 -> 1.0268604e+09 | H14: =Inputs_Supply!G15 -> 1.557498e+09 | I14: =H14-G14 -> 5.3063756e+08 | J14: =(H14/G14)-1 -> 0.51675724
B15: 2038 | C15: =IF('Trade-off Analysis'!$C$2='Trade-off Analysis'!$I$3,Inputs_Population!D41,IF('Trade-off Analysis'!$C$2='Trade-off Analysis'!$I$4,Inputs_Population!E41,Inputs_Population!F41)) -> 7935418.7 | D15: =Inputs_Tariff!H16 -> 154.13939 | E15: =C15*D15*365/1000 -> 4.4645363e+08 | F15: =E15/45*(55+(70-55)*(B15-2025)/35) -> 6.0094076e+08 | G15: =E15+F15 -> 1.0473944e+09 | H15: =Inputs_Supply!G16 -> 1.557498e+09 | I15: =H15-G15 -> 5.101036e+08 | J15: =(H15/G15)-1 -> 0.48702152
B16: 2039 | C16: =IF('Trade-off Analysis'!$C$2='Trade-off Analysis'!$I$3,Inputs_Population!D42,IF('Trade-off Analysis'!$C$2='Trade-off Analysis'!$I$4,Inputs_Population!E42,Inputs_Population!F42)) -> 8043979.3 | D16: =Inputs_Tariff!H17 -> 154.42424 | E16: =C16*D16*365/1000 -> 4.5339767e+08 | F16: =E16/45*(55+(70-55)*(B16-2025)/35) -> 6.1460573e+08 | G16: =E16+F16 -> 1.0680034e+09 | H16: =Inputs_Supply!G17 -> 1.557498e+09 | I16: =H16-G16 -> 4.8949458e+08 | J16: =(H16/G16)-1 -> 0.4583268
B17: 2040 | C17: =IF('Trade-off Analysis'!$C$2='Trade-off Analysis'!$I$3,Inputs_Population!D43,IF('Trade-off Analysis'!$C$2='Trade-off Analysis'!$I$4,Inputs_Population!E43,Inputs_Population!F43)) -> 8151787.3 | D17: =Inputs_Tariff!H18 -> 154.70909 | E17: =C17*D17*365/1000 -> 4.603218e+08 | F17: =E17/45*(55+(70-55)*(B17-2025)/35) -> 6.2837578e+08 | G17: =E17+F17 -> 1.0886976e+09 | H17: =Inputs_Supply!G18 -> 1.557498e+09 | I17: =H17-G17 -> 4.6880041e+08 | J17: =(H17/G17)-1 -> 0.43060664
B18: 2041 | C18: =IF('Trade-off Analysis'!$C$2='Trade-off Analysis'!$I$3,Inputs_Population!D44,IF('Trade-off Analysis'!$C$2='Trade-off Analysis'!$I$4,Inputs_Population!E44,Inputs_Population!F44)) -> 8258914.7 | D18: =Inputs_Tariff!H19 -> 154.99394 | E18: =C18*D18*365/1000 -> 4.6722983e+08 | F18: =E18/45*(55+(70-55)*(B18-2025)/35) -> 6.4225561e+08 | G18: =E18+F18 -> 1.1094854e+09 | H18: =Inputs_Supply!G19 -> 1.557498e+09 | I18: =H18-G18 -> 4.4801255e+08 | J18: =(H18/G18)-1 -> 0.4038021
B19: 2042 | C19: =IF('Trade-off Analysis'!$C$2='Trade-off Analysis'!$I$3,Inputs_Population!D45,IF('Trade-off Analysis'!$C$2='Trade-off Analysis'!$I$4,Inputs_Population!E45,Inputs_Population!F45)) -> 8365422.8 | D19: =Inputs_Tariff!H20 -> 155.27879 | E19: =C19*D19*365/1000 -> 4.7412504e+08 | F19: =E19/45*(55+(70-55)*(B19-2025)/35) -> 6.5624926e+08 | G19: =E19+F19 -> 1.1303743e+09 | H19: =Inputs_Supply!G20 -> 1.557498e+09 | I19: =H19-G19 -> 4.2712369e+08 | J19: =(H19/G19)-1 -> 0.3778604
B20: 2043 | C20: =IF('Trade-off Analysis'!$C$2='Trade-off Analysis'!$I$3,Inputs_Population!D46,IF('Trade-off Analysis'!$C$2='Trade-off Analysis'!$I$4,Inputs_Population!E46,Inputs_Population!F46)) -> 8471364.3 | D20: =Inputs_Tariff!H21 -> 155.56364 | E20: =C20*D20*365/1000 -> 4.8101023e+08 | F20: =E20/45*(55+(70-55)*(B20-2025)/35) -> 6.7036029e+08 | G20: =E20+F20 -> 1.1513705e+09 | H20: =Inputs_Supply!G21 -> 1.557498e+09 | I20: =H20-G20 -> 4.0612747e+08 | J20: =(H20/G20)-1 -> 0.35273395
B21: 2044 | C21: =IF('Trade-off Analysis'!$C$2='Trade-off Analysis'!$I$3,Inputs_Population!D47,IF('Trade-off Analysis'!$C$2='Trade-off Analysis'!$I$4,Inputs_Population!E47,Inputs_Population!F47)) -> 8576785.2 | D21: =Inputs_Tariff!H22 -> 155.84848 | E21: =C21*D21*365/1000 -> 4.8788783e+08 | F21: =E21/45*(55+(70-55)*(B21-2025)/35) -> 6.8459181e+08 | G21: =E21+F21 -> 1.1724796e+09 | H21: =Inputs_Supply!G22 -> 1.557498e+09 | I21: =H21-G21 -> 3.8501836e+08 | J21: =(H21/G21)-1 -> 0.32837957
B22: 2045 | C22: =IF('Trade-off Analysis'!$C$2='Trade-off Analysis'!$I$3,Inputs_Population!D48,IF('Trade-off Analysis'!$C$2='Trade-off Analysis'!$I$4,Inputs_Population!E48,Inputs_Population!F48)) -> 8681725.3 | D22: =Inputs_Tariff!H23 -> 156.13333 | E22: =C22*D22*365/1000 -> 4.9475995e+08 | F22: =E22/45*(55+(70-55)*(B22-2025)/35) -> 6.989466e+08 | G22: =E22+F22 -> 1.1937065e+09 | H22: =Inputs_Supply!G23 -> 1.557498e+09 | I22: =H22-G22 -> 3.6379144e+08 | J22: =(H22/G22)-1 -> 0.30475785
... B37: 2060 | C37: =IF('Trade-off Analysis'!$C$2='Trade-off Analysis'!$I$3,Inputs_Population!D63,IF('Trade-off Analysis'!$C$2='Trade-off Analysis'!$I$4,Inputs_Population!E63,Inputs_Population!F63)) -> 10215289 | D37: =Inputs_Tariff!H38 -> 148.5956 | E37: =C37*D37*365/1000 -> 5.5405067e+08 | F37: =E37/45*(55+(70-55)*(B37-2025)/35) -> 8.6185659e+08 | G37: =E37+F37 -> 1.4159073e+09 | H37: =Inputs_Supply!G38 -> 1.557498e+09 | I37: =H37-G37 -> 1.4159073e+08 | J37: =(H37/G37)-1 -> 0.1

Sheet Trade-off Analysis
B2: Population Scenario | C2: High | E2: Year | F2: TariffIncrease_% | G2: ReserveMargin_% | I2: Scenarios
B3: Consumption Scenario | C3: Baseline | E3: 2026 | F3: 0 | G3: =Model_Core!J3 -> 0.29040672 | I3: Baseline
B4: Tariff minimum | C4: =MIN(Inputs_Tariff!D4:D38) -> 1.43 | E4: 2027 | F4: 0 | G4: =Model_Core!J4 -> 0.54048421 | I4: Low
B5: Tariff maximum | C5: =MAX(Inputs_Tariff!D4:D38) -> 3.8057804 | E5: 2028 | F5: 0 | G5: =Model_Core!J5 -> 0.50086281 | I5: High
B6: Reserve margin minimum | C6: =MIN(Model_Core!J3:J37) -> 0.099999161 | E6: 2029 | F6: 0 | G6: =Model_Core!J6 -> 0.46415044
B7: Tariff Increase | C7: =AVERAGE(Inputs_Tariff!F4:F38) -> 0.03154738 | E7: 2030 | F7: 0 | G7: =Model_Core!J7 -> 0.42971546
E8: 2031 | F8: 0 | G8: =Model_Core!J8 -> 0.39716843
E9: 2032 | F9: 0 | G9: =Model_Core!J9 -> 0.36624323
B10: Documentation for Solver | E10: 2033 | F10: 0 | G10: =Model_Core!J10 -> 0.33674506
B11: Objective cell | C11: B3 | D11: Minimize | E11: 2034 | F11: 0 | G11: =Model_Core!J11 -> 0.30852399
B12: Changing cell | C12: F2:F36 | E12: 2035 | F12: 0 | G12: =Model_Core!J12 -> 0.57966558
B13: Constraints: | E13: 2036 | F13: 0 | G13: =Model_Core!J13 -> 0.54760956
B14: Tariff minimum | C14: C4 | D14: >=1.1 | E14: 2037 | F14: 0 | G14: =Model_Core!J14 -> 0.51675724
B15: Tariff maximum | C15: C5 | D15: <optional input> | E15: 2038 | F15: 0 | G15: =Model_Core!J15 -> 0.48702152
B16: Reserve margin | C16: G3:G37 | D16: >=10% | E16: 2039 | F16: 0 | G16: =Model_Core!J16 -> 0.4583268
E17: 2040 | F17: 0 | G17: =Model_Core!J17 -> 0.43060664
E18: 2041 | F18: 0 | G18: =Model_Core!J18 -> 0.4038021
B19: Documentation2 | E19: 2042 | F19: 0 | G19: =Model_Core!J19 -> 0.3778604
B20: Population Scenario | C20: C2 | D20: List from I3:I5 | E20: 2043 | F20: 0 | G20: =Model_Core!J20 -> 0.35273395
B21: Consumption Scenario | C21: C3 | D21: List from I3:I5 | E21: 2044 | F21: 0 | G21: =Model_Core!J21 -> 0.32837957
B22: Tariff minimum | C22: C4 | D22: =MIN(Inputs_Tariff!C4:C38) | E22: 2045 | F22: 0 | G22: =Model_Core!J22 -> 0.30475785
B23: Tariff maximum | C23: C5 | D23: =MAX(Inputs_Tariff!C4:C38) | E23: 2046 | F23: 0 | G23: =Model_Core!J23 -> 0.28183267
B24: Reserve margin minimum | C24: C6 | D24: =MIN(Model_Core!J3:J37) | E24: 2047 | F24: 0 | G24: =Model_Core!J24 -> 0.25957076
B25: Tariff Increase | C25: C7 | D25: =AVERAGE(Inputs_Tariff!E4:E38) | E25: 2048 | F25: 0 | G25: =Model_Core!J25 -> 0.2379414
E26: 2049 | F26: 0 | G26: =Model_Core!J26 -> 0.21691608
E27: 2050 | F27: 0 | G27: =Model_Core!J27 -> 0.19646829
E28: 2051 | F28: 0 | G28: =Model_Core!J28 -> 0.17657332
E29: 2052 | F29: 0 | G29: =Model_Core!J29 -> 0.15720805
E30: 2053 | F30: 0 | G30: =Model_Core!J30 -> 0.13835084
E31: 2054 | F31: 0 | G31: =Model_Core!J31 -> 0.11998136
E32: 2055 | F32: 0 | G32: =Model_Core!J32 -> 0.10208049
E33: 2056 | F33: 0.069858901 | G33: =Model_Core!J33 -> 0.099999161
E34: 2057 | F34: 0.14721119 | G34: =Model_Core!J34 -> 0.1
E35: 2058 | F35: 0.22266187 | G35: =Model_Core!J35 -> 0.1
E36: 2059 | F36: 0.29628382 | G36: =Model_Core!J36 -> 0.1
E37: 2060 | F37: 0.36814253 | G37: =Model_Core!J37 -> 0.1

Sheet Sensitivity Analysis
D2: Sensitivity of Reserve Security to Tariff Elasticity
B3: Year | C3: ReserveMargin_% | D3: -0.1 | E3: -0.2 | F3: -0.3 | G3: -0.4 | H3: -0.5 | I3: -0.6 | J3: -0.7 | K3: -0.8 | L3: -0.9 | M3: -1
B4: 2026 | C4: =Model_Core!J3 -> 0.29040672 | D4: 0.29040672 | E4: 0.29040672 | F4: 0.29040672 | G4: 0.29040672 | H4: 0.29040672 | I4: 0.29040672 | J4: 0.29040672 | K4: 0.29040672 | L4: 0.29040672 | M4: 0.29040672
B5: 2027 | C5: =Model_Core!J4 -> 0.54048421 | D5: 0.54048421 | E5: 0.54048421 | F5: 0.54048421 | G5: 0.54048421 | H5: 0.54048421 | I5: 0.54048421 | J5: 0.54048421 | K5: 0.54048421 | L5: 0.54048421 | M5: 0.54048421
B6: 2028 | C6: =Model_Core!J5 -> 0.50086281 | D6: 0.50086281 | E6: 0.50086281 | F6: 0.50086281 | G6: 0.50086281 | H6: 0.50086281 | I6: 0.50086281 | J6: 0.50086281 | K6: 0.50086281 | L6: 0.50086281 | M6: 0.50086281
B7: 2029 | C7: =Model_Core!J6 -> 0.46415044 | D7: 0.46415044 | E7: 0.46415044 | F7: 0.46415044 | G7: 0.46415044 | H7: 0.46415044 | I7: 0.46415044 | J7: 0.46415044 | K7: 0.46415044 | L7: 0.46415044 | M7: 0.46415044
B8: 2030 | C8: =Model_Core!J7 -> 0.42971546 | D8: 0.42971546 | E8: 0.42971546 | F8: 0.42971546 | G8: 0.42971546 | H8: 0.42971546 | I8: 0.42971546 | J8: 0.42971546 | K8: 0.42971546 | L8: 0.42971546 | M8: 0.42971546
B9: 2031 | C9: =Model_Core!J8 -> 0.39716843 | D9: 0.39716843 | E9: 0.39716843 | F9: 0.39716843 | G9: 0.39716843 | H9: 0.39716843 | I9: 0.39716843 | J9: 0.39716843 | K9: 0.39716843 | L9: 0.39716843 | M9: 0.39716843
B10: 2032 | C10: =Model_Core!J9 -> 0.36624323 | D10: 0.36624323 | E10: 0.36624323 | F10: 0.36624323 | G10: 0.36624323 | H10: 0.36624323 | I10: 0.36624323 | J10: 0.36624323 | K10: 0.36624323 | L10: 0.36624323 | M10: 0.36624323
B11: 2033 | C11: =Model_Core!J10 -> 0.33674506 | D11: 0.33674506 | E11: 0.33674506 | F11: 0.33674506 | G11: 0.33674506 | H11: 0.33674506 | I11: 0.33674506 | J11: 0.33674506 | K11: 0.33674506 | L11: 0.33674506 | M11: 0.33674506
B12: 2034 | C12: =Model_Core!J11 -> 0.30852399 | D12: 0.30852399 | E12: 0.30852399 | F12: 0.30852399 | G12: 0.30852399 | H12: 0.30852399 | I12: 0.30852399 | J12: 0.30852399 | K12: 0.30852399 | L12: 0.30852399 | M12: 0.30852399
B13: 2035 | C13: =Model_Core!J12 -> 0.57966558 | D13: 0.57966558 | E13: 0.57966558 | F13: 0.57966558 | G13: 0.57966558 | H13: 0.57966558 | I13: 0.57966558 | J13: 0.57966558 | K13: 0.57966558 | L13: 0.57966558 | M13: 0.57966558
B14: 2036 | C14: =Model_Core!J13 -> 0.54760956 | D14: 0.54760956 | E14: 0.54760956 | F14: 0.54760956 | G14: 0.54760956 | H14: 0.54760956 | I14: 0.54760956 | J14: 0.54760956 | K14: 0.54760956 | L14: 0.54760956 | M14: 0.54760956
B15: 2037 | C15: =Model_Core!J14 -> 0.51675724 | D15: 0.51675724 | E15: 0.51675724 | F15: 0.51675724 | G15: 0.51675724 | H15: 0.51675724 | I15: 0.51675724 | J15: 0.51675724 | K15: 0.51675724 | L15: 0.51675724 | M15: 0.51675724
... B38: 2060 | C38: =Model_Core!J37 -> 0.1 | D38: 0.057956523 | E38: 0.1 | F38: 0.14552341 | G38: 0.19497745 | H38: 0.24889417 | I38: 0.30790618 | J38: 0.37277156 | K38: 0.44440666 | L38: 0.52392961 | M38: 0.61271915
B40: Year | C40: ReserveMargin_% | D40: -0.1 | E40: -0.2 | F40: -0.3 | G40: -0.4 | H40: -0.5 | I40: -0.6 | J40: -0.7 | K40: -0.8 | L40: -0.9 | M40: -1
B41: 2060 | C41: =VLOOKUP($B$41,$B$4:$M$38,2,FALSE) -> 0.1 | D41: =VLOOKUP($B$41,$B$4:$M$38,3,FALSE) -> 0.057956523 | E41: =VLOOKUP($B$41,$B$4:$M$38,4,FALSE) -> 0.1 | F41: =VLOOKUP($B$41,$B$4:$M$38,5,FALSE) -> 0.14552341 | G41: =VLOOKUP($B$41,$B$4:$M$38,6,FALSE) -> 0.19497745 | H41: =VLOOKUP($B$41,$B$4:$M$38,7,FALSE) -> 0.24889417 | I41: =VLOOKUP($B$41,$B$4:$M$38,8,FALSE) -> 0.30790618 | J41: =VLOOKUP($B$41,$B$4:$M$38,9,FALSE) -> 0.37277156 | K41: =VLOOKUP($B$41,$B$4:$M$38,10,FALSE) -> 0.44440666 | L41: =VLOOKUP($B$41,$B$4:$M$38,11,FALSE) -> 0.52392961 | M41: =VLOOKUP($B$41,$B$4:$M$38,12,FALSE) -> 0.61271915
B42: ="Tariff_Inc%: "&TEXT(VLOOKUP(B41,'Trade-off Analysis'!E3:F37,2,0), "0%") -> Tariff_Inc%: 37% | C42: Margin change | D42: =(D41-$C$41) -> -0.042043477 | E42: =(E41-$C$41) -> 0 | F42: =(F41-$C$41) -> 0.045523409 | G42: =(G41-$C$41) -> 0.094977452 | H42: =(H41-$C$41) -> 0.14889417 | I42: =(I41-$C$41) -> 0.20790618 | J42: =(J41-$C$41) -> 0.27277156 | K42: =(K41-$C$41) -> 0.34440666 | ... M42: =(M41-$C$41) -> 0.51271915
B44: Row input cell | C44: -0.2
B45: Note: | C45: Cell 'Trade-off Analysis'!F3:F37 must be more than 0% for the Sensitivity Table to work
B47: Documentation
B48: Sensitivity Table | C48: C2:C37
B49: Row input cell | C49: C39
B51: Margin change table
B52: Year selection | C52: B40 | D52: List from B3:B37
B53: ReserveMargin_% | C53: C40:M40 | D53: =VLOOKUP($B$40,$B$3:$M$37,2,FALSE)
B54: Margin change | C54: C41:M41 | D54: =(D40-$C$40)
B55: Tariff Increase % | C55: B41 | D55: ="Tariff_Inc%: "&TEXT(VLOOKUP(B40,'Trade-off Analysis'!E3:F37,2,0), "0%")

Sheet Results_Dashboard
B2: Year | C2: TotalDemand_m3 | D2: TotalSupply_m3 | E2: ReserveMargin_%
